{
 "cells": [
  {
   "cell_type": "code",
   "execution_count": 1,
   "id": "22b90339",
   "metadata": {},
   "outputs": [
    {
     "name": "stdout",
     "output_type": "stream",
     "text": [
      "PyAEDT INFO: Python version 3.11.5 | packaged by Anaconda, Inc. | (main, Sep 11 2023, 13:26:23) [MSC v.1916 64 bit (AMD64)].\n",
      "PyAEDT INFO: PyAEDT version 0.18.1.\n",
      "PyAEDT INFO: Initializing new Desktop session.\n",
      "PyAEDT INFO: Log on console is enabled.\n",
      "PyAEDT INFO: Log on file C:\\Users\\chen\\AppData\\Local\\Temp\\pyaedt_chen_6361785f-5f0b-48fa-ab9a-630743080ea7.log is enabled.\n",
      "PyAEDT INFO: Log on AEDT is disabled.\n",
      "PyAEDT INFO: Debug logger is disabled. PyAEDT methods will not be logged.\n",
      "PyAEDT INFO: Launching PyAEDT with gRPC plugin.\n"
     ]
    },
    {
     "name": "stderr",
     "output_type": "stream",
     "text": [
      "d:\\anaconda3\\envs\\qeda_env\\Lib\\site-packages\\pandas\\core\\arrays\\masked.py:60: UserWarning: Pandas requires version '1.3.6' or newer of 'bottleneck' (version '1.3.5' currently installed).\n",
      "  from pandas.core import (\n"
     ]
    },
    {
     "name": "stdout",
     "output_type": "stream",
     "text": [
      "PyAEDT INFO: New AEDT session is starting on gRPC port 52955.\n",
      "PyAEDT INFO: Electronics Desktop started on gRPC port: 52955 after 6.922586679458618 seconds.\n",
      "PyAEDT INFO: AEDT installation Path D:\\Program Files\\AnsysEM\\v241\\Win64\n",
      "PyAEDT INFO: Ansoft.ElectronicsDesktop.2024.1 version started with process ID 47128.\n",
      "PyAEDT INFO: Python version 3.11.5 | packaged by Anaconda, Inc. | (main, Sep 11 2023, 13:26:23) [MSC v.1916 64 bit (AMD64)].\n",
      "PyAEDT INFO: PyAEDT version 0.18.1.\n",
      "PyAEDT INFO: Returning found Desktop session with PID 47128!\n",
      "PyAEDT INFO: Project project has been created.\n",
      "PyAEDT INFO: No design is present. Inserting a new design.\n",
      "PyAEDT INFO: Added design 'Q3D Extractor_CSG' of type Q3D Extractor.\n",
      "PyAEDT INFO: Aedt Objects correctly read\n",
      "111\n",
      "Cell: chip0\n",
      "Cell: gds\n",
      "layer:  {3: (0, 0)}\n",
      "PyAEDT INFO: GDS layer imported with elevations and thickness.\n",
      "merged  {}\n",
      "0\n",
      "(-0.4, -0.5) 1.7999999999999998 2.0\n",
      "Starting simulation: dz=0.007 mm\n",
      "PyAEDT ERROR: Dictionary for GDSII layer numbers is empty. No layer is imported.\n",
      "PyAEDT INFO: Modeler class has been initialized! Elapsed time: 0m 0sec\n",
      "[]\n",
      "PyAEDT ERROR: **************************************************************\n",
      "PyAEDT ERROR:   File \"<frozen runpy>\", line 198, in _run_module_as_main\n",
      "PyAEDT ERROR:   File \"<frozen runpy>\", line 88, in _run_code\n",
      "PyAEDT ERROR:   File \"d:\\anaconda3\\envs\\qeda_env\\Lib\\asyncio\\base_events.py\", line 607, in run_forever\n",
      "PyAEDT ERROR:     self._run_once()\n",
      "PyAEDT ERROR:   File \"d:\\anaconda3\\envs\\qeda_env\\Lib\\asyncio\\base_events.py\", line 1922, in _run_once\n",
      "PyAEDT ERROR:     handle._run()\n",
      "PyAEDT ERROR:   File \"d:\\anaconda3\\envs\\qeda_env\\Lib\\asyncio\\events.py\", line 80, in _run\n",
      "PyAEDT ERROR:     self._context.run(self._callback, *self._args)\n",
      "PyAEDT ERROR:   File \"C:\\Users\\chen\\AppData\\Local\\Temp\\ipykernel_47456\\1168869540.py\", line 13, in <module>\n",
      "PyAEDT ERROR:     ei.run_q3d_extraction_from_gds(gds_name)\n",
      "PyAEDT ERROR:   File \"d:\\5j\\EDA-Q\\test\\..\\renderer\\q3d\\capative.py\", line 360, in run_q3d_extraction_from_gds\n",
      "PyAEDT ERROR:     run_q3d_extraction_default(merged, start_point_1 , dx , dy ,dz = thickness[i] )\n",
      "PyAEDT ERROR:   File \"d:\\5j\\EDA-Q\\test\\..\\renderer\\q3d\\capative.py\", line 204, in run_q3d_extraction_default\n",
      "PyAEDT ERROR:     region = q3d.modeler.create_region(\n",
      "PyAEDT ERROR: Can only concatenate str (not \"nonetype\") to str on _parse_region_args\n",
      "PyAEDT ERROR: Method arguments: \n",
      "PyAEDT ERROR:     pad_value = ['0', 0, 0, 0, 1, 1] \n",
      "PyAEDT ERROR:     pad_type = ['Percentage Offset', 'Percentage Offset', 'Percentage Offset', 'Percentage Offset', 'Absolute Offset', 'Absolute Offset'] \n",
      "PyAEDT ERROR:     region_name = region \n",
      "PyAEDT ERROR:     region_type = Region \n",
      "PyAEDT ERROR: **************************************************************\n",
      "PyAEDT ERROR: **************************************************************\n",
      "PyAEDT ERROR:   File \"<frozen runpy>\", line 198, in _run_module_as_main\n",
      "PyAEDT ERROR:   File \"<frozen runpy>\", line 88, in _run_code\n",
      "PyAEDT ERROR:   File \"d:\\anaconda3\\envs\\qeda_env\\Lib\\asyncio\\base_events.py\", line 607, in run_forever\n",
      "PyAEDT ERROR:     self._run_once()\n",
      "PyAEDT ERROR:   File \"d:\\anaconda3\\envs\\qeda_env\\Lib\\asyncio\\base_events.py\", line 1922, in _run_once\n",
      "PyAEDT ERROR:     handle._run()\n",
      "PyAEDT ERROR:   File \"d:\\anaconda3\\envs\\qeda_env\\Lib\\asyncio\\events.py\", line 80, in _run\n",
      "PyAEDT ERROR:     self._context.run(self._callback, *self._args)\n",
      "PyAEDT ERROR:   File \"C:\\Users\\chen\\AppData\\Local\\Temp\\ipykernel_47456\\1168869540.py\", line 13, in <module>\n",
      "PyAEDT ERROR:     ei.run_q3d_extraction_from_gds(gds_name)\n",
      "PyAEDT ERROR:   File \"d:\\5j\\EDA-Q\\test\\..\\renderer\\q3d\\capative.py\", line 360, in run_q3d_extraction_from_gds\n",
      "PyAEDT ERROR:     run_q3d_extraction_default(merged, start_point_1 , dx , dy ,dz = thickness[i] )\n",
      "PyAEDT ERROR:   File \"d:\\5j\\EDA-Q\\test\\..\\renderer\\q3d\\capative.py\", line 204, in run_q3d_extraction_default\n",
      "PyAEDT ERROR:     region = q3d.modeler.create_region(\n",
      "PyAEDT ERROR: Cannot unpack non-iterable bool object on _create_region\n",
      "PyAEDT ERROR: Method arguments: \n",
      "PyAEDT ERROR:     pad_value = ['0', 0, 0, 0, 1, 1] \n",
      "PyAEDT ERROR:     pad_type = ['Percentage Offset', 'Percentage Offset', 'Percentage Offset', 'Percentage Offset', 'Absolute Offset', 'Absolute Offset'] \n",
      "PyAEDT ERROR:     name = region \n",
      "PyAEDT ERROR:     region_type = Region \n",
      "PyAEDT ERROR: **************************************************************\n",
      "PyAEDT INFO: Materials class has been initialized! Elapsed time: 0m 0sec\n",
      "PyAEDT ERROR: **************************************************************\n",
      "PyAEDT ERROR:   File \"<frozen runpy>\", line 198, in _run_module_as_main\n",
      "PyAEDT ERROR:   File \"<frozen runpy>\", line 88, in _run_code\n",
      "PyAEDT ERROR:   File \"d:\\anaconda3\\envs\\qeda_env\\Lib\\asyncio\\base_events.py\", line 607, in run_forever\n",
      "PyAEDT ERROR:     self._run_once()\n",
      "PyAEDT ERROR:   File \"d:\\anaconda3\\envs\\qeda_env\\Lib\\asyncio\\base_events.py\", line 1922, in _run_once\n",
      "PyAEDT ERROR:     handle._run()\n",
      "PyAEDT ERROR:   File \"d:\\anaconda3\\envs\\qeda_env\\Lib\\asyncio\\events.py\", line 80, in _run\n",
      "PyAEDT ERROR:     self._context.run(self._callback, *self._args)\n",
      "PyAEDT ERROR:   File \"C:\\Users\\chen\\AppData\\Local\\Temp\\ipykernel_47456\\1168869540.py\", line 13, in <module>\n",
      "PyAEDT ERROR:     ei.run_q3d_extraction_from_gds(gds_name)\n",
      "PyAEDT ERROR:   File \"d:\\5j\\EDA-Q\\test\\..\\renderer\\q3d\\capative.py\", line 360, in run_q3d_extraction_from_gds\n",
      "PyAEDT ERROR:     run_q3d_extraction_default(merged, start_point_1 , dx , dy ,dz = thickness[i] )\n",
      "PyAEDT ERROR:   File \"d:\\5j\\EDA-Q\\test\\..\\renderer\\q3d\\capative.py\", line 210, in run_q3d_extraction_default\n",
      "PyAEDT ERROR:     q3d.assign_material(region , 'vacuum')\n",
      "PyAEDT ERROR: 'nonetype' object has no attribute 'getlibrarydirectory' on _read_materials\n",
      "PyAEDT ERROR: **************************************************************\n",
      "PyAEDT ERROR: **************************************************************\n",
      "PyAEDT ERROR:   File \"<frozen runpy>\", line 198, in _run_module_as_main\n",
      "PyAEDT ERROR:   File \"<frozen runpy>\", line 88, in _run_code\n",
      "PyAEDT ERROR:   File \"d:\\anaconda3\\envs\\qeda_env\\Lib\\asyncio\\base_events.py\", line 607, in run_forever\n",
      "PyAEDT ERROR:     self._run_once()\n",
      "PyAEDT ERROR:   File \"d:\\anaconda3\\envs\\qeda_env\\Lib\\asyncio\\base_events.py\", line 1922, in _run_once\n",
      "PyAEDT ERROR:     handle._run()\n",
      "PyAEDT ERROR:   File \"d:\\anaconda3\\envs\\qeda_env\\Lib\\asyncio\\events.py\", line 80, in _run\n",
      "PyAEDT ERROR:     self._context.run(self._callback, *self._args)\n",
      "PyAEDT ERROR:   File \"C:\\Users\\chen\\AppData\\Local\\Temp\\ipykernel_47456\\1168869540.py\", line 13, in <module>\n",
      "PyAEDT ERROR:     ei.run_q3d_extraction_from_gds(gds_name)\n",
      "PyAEDT ERROR:   File \"d:\\5j\\EDA-Q\\test\\..\\renderer\\q3d\\capative.py\", line 360, in run_q3d_extraction_from_gds\n",
      "PyAEDT ERROR:     run_q3d_extraction_default(merged, start_point_1 , dx , dy ,dz = thickness[i] )\n",
      "PyAEDT ERROR:   File \"d:\\5j\\EDA-Q\\test\\..\\renderer\\q3d\\capative.py\", line 210, in run_q3d_extraction_default\n",
      "PyAEDT ERROR:     q3d.assign_material(region , 'vacuum')\n",
      "PyAEDT ERROR: Object of type 'bool' has no len() on _get_aedt_case_name\n",
      "PyAEDT ERROR: Method arguments: \n",
      "PyAEDT ERROR:     material_name = vacuum \n",
      "PyAEDT ERROR: **************************************************************\n",
      "PyAEDT ERROR: Material does not exist.\n",
      "PyAEDT ERROR: **************************************************************\n",
      "PyAEDT ERROR:   File \"<frozen runpy>\", line 198, in _run_module_as_main\n",
      "PyAEDT ERROR:   File \"<frozen runpy>\", line 88, in _run_code\n",
      "PyAEDT ERROR:   File \"d:\\anaconda3\\envs\\qeda_env\\Lib\\asyncio\\base_events.py\", line 607, in run_forever\n",
      "PyAEDT ERROR:     self._run_once()\n",
      "PyAEDT ERROR:   File \"d:\\anaconda3\\envs\\qeda_env\\Lib\\asyncio\\base_events.py\", line 1922, in _run_once\n",
      "PyAEDT ERROR:     handle._run()\n",
      "PyAEDT ERROR:   File \"d:\\anaconda3\\envs\\qeda_env\\Lib\\asyncio\\events.py\", line 80, in _run\n",
      "PyAEDT ERROR:     self._context.run(self._callback, *self._args)\n",
      "PyAEDT ERROR:   File \"C:\\Users\\chen\\AppData\\Local\\Temp\\ipykernel_47456\\1168869540.py\", line 13, in <module>\n",
      "PyAEDT ERROR:     ei.run_q3d_extraction_from_gds(gds_name)\n",
      "PyAEDT ERROR:   File \"d:\\5j\\EDA-Q\\test\\..\\renderer\\q3d\\capative.py\", line 360, in run_q3d_extraction_from_gds\n",
      "PyAEDT ERROR:     run_q3d_extraction_default(merged, start_point_1 , dx , dy ,dz = thickness[i] )\n",
      "PyAEDT ERROR:   File \"d:\\5j\\EDA-Q\\test\\..\\renderer\\q3d\\capative.py\", line 263, in run_q3d_extraction_default\n",
      "PyAEDT ERROR:     output = find_resonance(1)\n",
      "PyAEDT ERROR:   File \"d:\\5j\\EDA-Q\\test\\..\\renderer\\q3d\\capative.py\", line 226, in find_resonance\n",
      "PyAEDT ERROR:     setup = q3d.create_setup(setup_name)\n",
      "PyAEDT ERROR: Argument of type 'nonetype' is not iterable on _initialize_tree_node\n",
      "PyAEDT ERROR: **************************************************************\n",
      "PyAEDT ERROR: **************************************************************\n",
      "PyAEDT ERROR:   File \"<frozen runpy>\", line 198, in _run_module_as_main\n",
      "PyAEDT ERROR:   File \"<frozen runpy>\", line 88, in _run_code\n",
      "PyAEDT ERROR:   File \"d:\\anaconda3\\envs\\qeda_env\\Lib\\asyncio\\base_events.py\", line 607, in run_forever\n",
      "PyAEDT ERROR:     self._run_once()\n",
      "PyAEDT ERROR:   File \"d:\\anaconda3\\envs\\qeda_env\\Lib\\asyncio\\base_events.py\", line 1922, in _run_once\n",
      "PyAEDT ERROR:     handle._run()\n",
      "PyAEDT ERROR:   File \"d:\\anaconda3\\envs\\qeda_env\\Lib\\asyncio\\events.py\", line 80, in _run\n",
      "PyAEDT ERROR:     self._context.run(self._callback, *self._args)\n",
      "PyAEDT ERROR:   File \"C:\\Users\\chen\\AppData\\Local\\Temp\\ipykernel_47456\\1168869540.py\", line 13, in <module>\n",
      "PyAEDT ERROR:     ei.run_q3d_extraction_from_gds(gds_name)\n",
      "PyAEDT ERROR:   File \"d:\\5j\\EDA-Q\\test\\..\\renderer\\q3d\\capative.py\", line 360, in run_q3d_extraction_from_gds\n",
      "PyAEDT ERROR:     run_q3d_extraction_default(merged, start_point_1 , dx , dy ,dz = thickness[i] )\n",
      "PyAEDT ERROR:   File \"d:\\5j\\EDA-Q\\test\\..\\renderer\\q3d\\capative.py\", line 263, in run_q3d_extraction_default\n",
      "PyAEDT ERROR:     output = find_resonance(1)\n",
      "PyAEDT ERROR:   File \"d:\\5j\\EDA-Q\\test\\..\\renderer\\q3d\\capative.py\", line 226, in find_resonance\n",
      "PyAEDT ERROR:     setup = q3d.create_setup(setup_name)\n",
      "PyAEDT ERROR: 'nonetype' object has no attribute 'insertsetup' on create\n",
      "PyAEDT ERROR: **************************************************************\n",
      "PyAEDT ERROR: **************************************************************\n",
      "PyAEDT ERROR:   File \"<frozen runpy>\", line 198, in _run_module_as_main\n",
      "PyAEDT ERROR:   File \"<frozen runpy>\", line 88, in _run_code\n",
      "PyAEDT ERROR:   File \"d:\\anaconda3\\envs\\qeda_env\\Lib\\asyncio\\base_events.py\", line 607, in run_forever\n",
      "PyAEDT ERROR:     self._run_once()\n",
      "PyAEDT ERROR:   File \"d:\\anaconda3\\envs\\qeda_env\\Lib\\asyncio\\base_events.py\", line 1922, in _run_once\n",
      "PyAEDT ERROR:     handle._run()\n",
      "PyAEDT ERROR:   File \"d:\\anaconda3\\envs\\qeda_env\\Lib\\asyncio\\events.py\", line 80, in _run\n",
      "PyAEDT ERROR:     self._context.run(self._callback, *self._args)\n",
      "PyAEDT ERROR:   File \"C:\\Users\\chen\\AppData\\Local\\Temp\\ipykernel_47456\\1168869540.py\", line 13, in <module>\n",
      "PyAEDT ERROR:     ei.run_q3d_extraction_from_gds(gds_name)\n",
      "PyAEDT ERROR:   File \"d:\\5j\\EDA-Q\\test\\..\\renderer\\q3d\\capative.py\", line 360, in run_q3d_extraction_from_gds\n",
      "PyAEDT ERROR:     run_q3d_extraction_default(merged, start_point_1 , dx , dy ,dz = thickness[i] )\n",
      "PyAEDT ERROR:   File \"d:\\5j\\EDA-Q\\test\\..\\renderer\\q3d\\capative.py\", line 263, in run_q3d_extraction_default\n",
      "PyAEDT ERROR:     output = find_resonance(1)\n",
      "PyAEDT ERROR:   File \"d:\\5j\\EDA-Q\\test\\..\\renderer\\q3d\\capative.py\", line 226, in find_resonance\n",
      "PyAEDT ERROR:     setup = q3d.create_setup(setup_name)\n",
      "PyAEDT ERROR: No setups defined. on active_setup\n",
      "PyAEDT ERROR: Method arguments: \n",
      "PyAEDT ERROR:     name = setup1 \n",
      "PyAEDT ERROR: **************************************************************\n",
      "PyAEDT ERROR: **************************************************************\n",
      "PyAEDT ERROR:   File \"<frozen runpy>\", line 198, in _run_module_as_main\n",
      "PyAEDT ERROR:   File \"<frozen runpy>\", line 88, in _run_code\n",
      "PyAEDT ERROR:   File \"d:\\anaconda3\\envs\\qeda_env\\Lib\\asyncio\\base_events.py\", line 607, in run_forever\n",
      "PyAEDT ERROR:     self._run_once()\n",
      "PyAEDT ERROR:   File \"d:\\anaconda3\\envs\\qeda_env\\Lib\\asyncio\\base_events.py\", line 1922, in _run_once\n",
      "PyAEDT ERROR:     handle._run()\n",
      "PyAEDT ERROR:   File \"d:\\anaconda3\\envs\\qeda_env\\Lib\\asyncio\\events.py\", line 80, in _run\n",
      "PyAEDT ERROR:     self._context.run(self._callback, *self._args)\n",
      "PyAEDT ERROR:   File \"C:\\Users\\chen\\AppData\\Local\\Temp\\ipykernel_47456\\1168869540.py\", line 13, in <module>\n",
      "PyAEDT ERROR:     ei.run_q3d_extraction_from_gds(gds_name)\n",
      "PyAEDT ERROR:   File \"d:\\5j\\EDA-Q\\test\\..\\renderer\\q3d\\capative.py\", line 360, in run_q3d_extraction_from_gds\n",
      "PyAEDT ERROR:     run_q3d_extraction_default(merged, start_point_1 , dx , dy ,dz = thickness[i] )\n",
      "PyAEDT ERROR:   File \"d:\\5j\\EDA-Q\\test\\..\\renderer\\q3d\\capative.py\", line 263, in run_q3d_extraction_default\n",
      "PyAEDT ERROR:     output = find_resonance(1)\n",
      "PyAEDT ERROR:   File \"d:\\5j\\EDA-Q\\test\\..\\renderer\\q3d\\capative.py\", line 226, in find_resonance\n",
      "PyAEDT ERROR:     setup = q3d.create_setup(setup_name)\n",
      "PyAEDT ERROR: 'nonetype' object has no attribute 'editsetup' on update\n",
      "PyAEDT ERROR: **************************************************************\n",
      "PyAEDT INFO: Key Adaptive Freq matched internal key 'AdaptiveFreq' with confidence of 96.\n",
      "PyAEDT ERROR: **************************************************************\n",
      "PyAEDT ERROR:   File \"<frozen runpy>\", line 198, in _run_module_as_main\n",
      "PyAEDT ERROR:   File \"<frozen runpy>\", line 88, in _run_code\n",
      "PyAEDT ERROR:   File \"d:\\anaconda3\\envs\\qeda_env\\Lib\\asyncio\\base_events.py\", line 607, in run_forever\n",
      "PyAEDT ERROR:     self._run_once()\n",
      "PyAEDT ERROR:   File \"d:\\anaconda3\\envs\\qeda_env\\Lib\\asyncio\\base_events.py\", line 1922, in _run_once\n",
      "PyAEDT ERROR:     handle._run()\n",
      "PyAEDT ERROR:   File \"d:\\anaconda3\\envs\\qeda_env\\Lib\\asyncio\\events.py\", line 80, in _run\n",
      "PyAEDT ERROR:     self._context.run(self._callback, *self._args)\n",
      "PyAEDT ERROR:   File \"C:\\Users\\chen\\AppData\\Local\\Temp\\ipykernel_47456\\1168869540.py\", line 13, in <module>\n",
      "PyAEDT ERROR:     ei.run_q3d_extraction_from_gds(gds_name)\n",
      "PyAEDT ERROR:   File \"d:\\5j\\EDA-Q\\test\\..\\renderer\\q3d\\capative.py\", line 360, in run_q3d_extraction_from_gds\n",
      "PyAEDT ERROR:     run_q3d_extraction_default(merged, start_point_1 , dx , dy ,dz = thickness[i] )\n",
      "PyAEDT ERROR:   File \"d:\\5j\\EDA-Q\\test\\..\\renderer\\q3d\\capative.py\", line 263, in run_q3d_extraction_default\n",
      "PyAEDT ERROR:     output = find_resonance(1)\n",
      "PyAEDT ERROR:   File \"d:\\5j\\EDA-Q\\test\\..\\renderer\\q3d\\capative.py\", line 227, in find_resonance\n",
      "PyAEDT ERROR:     setup['Adaptive Freq'] =  5 *1e9\n",
      "PyAEDT ERROR:   File \"d:\\anaconda3\\envs\\qeda_env\\Lib\\site-packages\\ansys\\aedt\\core\\modules\\solve_sweeps.py\", line 1007, in __setitem__\n",
      "PyAEDT ERROR:     res = self._pyaedt_setup.update()\n",
      "PyAEDT ERROR: 'nonetype' object has no attribute 'editsetup' on update\n",
      "PyAEDT ERROR: **************************************************************\n",
      "PyAEDT WARNING: Update of AdaptiveFreq failed. Check needed arguments\n",
      "PyAEDT ERROR: **************************************************************\n",
      "PyAEDT ERROR:   File \"<frozen runpy>\", line 198, in _run_module_as_main\n",
      "PyAEDT ERROR:   File \"<frozen runpy>\", line 88, in _run_code\n",
      "PyAEDT ERROR:   File \"d:\\anaconda3\\envs\\qeda_env\\Lib\\asyncio\\base_events.py\", line 607, in run_forever\n",
      "PyAEDT ERROR:     self._run_once()\n",
      "PyAEDT ERROR:   File \"d:\\anaconda3\\envs\\qeda_env\\Lib\\asyncio\\base_events.py\", line 1922, in _run_once\n",
      "PyAEDT ERROR:     handle._run()\n",
      "PyAEDT ERROR:   File \"d:\\anaconda3\\envs\\qeda_env\\Lib\\asyncio\\events.py\", line 80, in _run\n",
      "PyAEDT ERROR:     self._context.run(self._callback, *self._args)\n",
      "PyAEDT ERROR:   File \"C:\\Users\\chen\\AppData\\Local\\Temp\\ipykernel_47456\\1168869540.py\", line 13, in <module>\n",
      "PyAEDT ERROR:     ei.run_q3d_extraction_from_gds(gds_name)\n",
      "PyAEDT ERROR:   File \"d:\\5j\\EDA-Q\\test\\..\\renderer\\q3d\\capative.py\", line 360, in run_q3d_extraction_from_gds\n",
      "PyAEDT ERROR:     run_q3d_extraction_default(merged, start_point_1 , dx , dy ,dz = thickness[i] )\n",
      "PyAEDT ERROR:   File \"d:\\5j\\EDA-Q\\test\\..\\renderer\\q3d\\capative.py\", line 263, in run_q3d_extraction_default\n",
      "PyAEDT ERROR:     output = find_resonance(1)\n",
      "PyAEDT ERROR:   File \"d:\\5j\\EDA-Q\\test\\..\\renderer\\q3d\\capative.py\", line 227, in find_resonance\n",
      "PyAEDT ERROR:     setup['Adaptive Freq'] =  5 *1e9\n",
      "PyAEDT ERROR: 'nonetype' object has no attribute 'editsetup' on update\n",
      "PyAEDT ERROR: **************************************************************\n",
      "{}\n",
      "PyAEDT ERROR: **************************************************************\n",
      "PyAEDT ERROR:   File \"<frozen runpy>\", line 198, in _run_module_as_main\n",
      "PyAEDT ERROR:   File \"<frozen runpy>\", line 88, in _run_code\n",
      "PyAEDT ERROR:   File \"d:\\anaconda3\\envs\\qeda_env\\Lib\\asyncio\\base_events.py\", line 607, in run_forever\n",
      "PyAEDT ERROR:     self._run_once()\n",
      "PyAEDT ERROR:   File \"d:\\anaconda3\\envs\\qeda_env\\Lib\\asyncio\\base_events.py\", line 1922, in _run_once\n",
      "PyAEDT ERROR:     handle._run()\n",
      "PyAEDT ERROR:   File \"d:\\anaconda3\\envs\\qeda_env\\Lib\\asyncio\\events.py\", line 80, in _run\n",
      "PyAEDT ERROR:     self._context.run(self._callback, *self._args)\n",
      "PyAEDT ERROR:   File \"C:\\Users\\chen\\AppData\\Local\\Temp\\ipykernel_47456\\1168869540.py\", line 13, in <module>\n",
      "PyAEDT ERROR:     ei.run_q3d_extraction_from_gds(gds_name)\n",
      "PyAEDT ERROR:   File \"d:\\5j\\EDA-Q\\test\\..\\renderer\\q3d\\capative.py\", line 360, in run_q3d_extraction_from_gds\n",
      "PyAEDT ERROR:     run_q3d_extraction_default(merged, start_point_1 , dx , dy ,dz = thickness[i] )\n",
      "PyAEDT ERROR:   File \"d:\\5j\\EDA-Q\\test\\..\\renderer\\q3d\\capative.py\", line 263, in run_q3d_extraction_default\n",
      "PyAEDT ERROR:     output = find_resonance(1)\n",
      "PyAEDT ERROR:   File \"d:\\5j\\EDA-Q\\test\\..\\renderer\\q3d\\capative.py\", line 231, in find_resonance\n",
      "PyAEDT ERROR:     q3d.analyze_setup(setup_name, cores=num_cores, use_auto_settings=True)\n",
      "PyAEDT ERROR: Argument of type 'nonetype' is not iterable on analyze_setup\n",
      "PyAEDT ERROR: Method arguments: \n",
      "PyAEDT ERROR:     name = setup1 \n",
      "PyAEDT ERROR:     cores = 8 \n",
      "PyAEDT ERROR:     use_auto_settings = True \n",
      "PyAEDT ERROR: **************************************************************\n"
     ]
    },
    {
     "ename": "TypeError",
     "evalue": "argument of type 'NoneType' is not iterable",
     "output_type": "error",
     "traceback": [
      "\u001b[1;31m---------------------------------------------------------------------------\u001b[0m",
      "\u001b[1;31mTypeError\u001b[0m                                 Traceback (most recent call last)",
      "Cell \u001b[1;32mIn[1], line 13\u001b[0m\n\u001b[0;32m      9\u001b[0m gds_path \u001b[38;5;241m=\u001b[39m os\u001b[38;5;241m.\u001b[39mpath\u001b[38;5;241m.\u001b[39mjoin(base_dir, gds_name)\n\u001b[0;32m     11\u001b[0m ei \u001b[38;5;241m=\u001b[39m capacitance(project \u001b[38;5;241m=\u001b[39m \u001b[38;5;124m'\u001b[39m\u001b[38;5;124mproject\u001b[39m\u001b[38;5;124m'\u001b[39m , version \u001b[38;5;241m=\u001b[39m \u001b[38;5;124m'\u001b[39m\u001b[38;5;124m2024.1\u001b[39m\u001b[38;5;124m'\u001b[39m)\n\u001b[1;32m---> 13\u001b[0m ei\u001b[38;5;241m.\u001b[39mrun_q3d_extraction_from_gds(gds_name)\n",
      "File \u001b[1;32md:\\5j\\EDA-Q\\test\\..\\renderer\\q3d\\capative.py:360\u001b[0m, in \u001b[0;36mcapacitance.run_q3d_extraction_from_gds\u001b[1;34m(self, gds_name, thickness, basic_material, region_material)\u001b[0m\n\u001b[0;32m    358\u001b[0m     \u001b[38;5;28;01mfor\u001b[39;00m i \u001b[38;5;129;01min\u001b[39;00m \u001b[38;5;28mrange\u001b[39m(\u001b[38;5;241m0\u001b[39m , \u001b[38;5;28mlen\u001b[39m(thickness)):   \n\u001b[0;32m    359\u001b[0m         \u001b[38;5;28mprint\u001b[39m(start_point_1 ,dx , dy)\n\u001b[1;32m--> 360\u001b[0m         run_q3d_extraction_default(merged, start_point_1 , dx , dy ,dz \u001b[38;5;241m=\u001b[39m thickness[i] )\n\u001b[0;32m    363\u001b[0m d\u001b[38;5;241m.\u001b[39mrelease_desktop()\n",
      "File \u001b[1;32md:\\5j\\EDA-Q\\test\\..\\renderer\\q3d\\capative.py:263\u001b[0m, in \u001b[0;36mcapacitance.run_q3d_extraction_from_gds.<locals>.run_q3d_extraction_default\u001b[1;34m(layer, start_point, dx, dy, dz, num_cores)\u001b[0m\n\u001b[0;32m    260\u001b[0m     \u001b[38;5;28mprint\u001b[39m(df)\n\u001b[0;32m    261\u001b[0m     \u001b[38;5;28;01mreturn\u001b[39;00m df\n\u001b[1;32m--> 263\u001b[0m output \u001b[38;5;241m=\u001b[39m find_resonance(\u001b[38;5;241m1\u001b[39m)\n\u001b[0;32m    266\u001b[0m \u001b[38;5;66;03m# Save and close project\u001b[39;00m\n\u001b[0;32m    267\u001b[0m q3d\u001b[38;5;241m.\u001b[39msave_project()\n",
      "File \u001b[1;32md:\\5j\\EDA-Q\\test\\..\\renderer\\q3d\\capative.py:233\u001b[0m, in \u001b[0;36mcapacitance.run_q3d_extraction_from_gds.<locals>.run_q3d_extraction_default.<locals>.find_resonance\u001b[1;34m(setup_nr)\u001b[0m\n\u001b[0;32m    230\u001b[0m \u001b[38;5;66;03m# Analyze the Eigenmode setup\u001b[39;00m\n\u001b[0;32m    231\u001b[0m q3d\u001b[38;5;241m.\u001b[39manalyze_setup(setup_name, cores\u001b[38;5;241m=\u001b[39mnum_cores, use_auto_settings\u001b[38;5;241m=\u001b[39m\u001b[38;5;28;01mTrue\u001b[39;00m)\n\u001b[1;32m--> 233\u001b[0m result \u001b[38;5;241m=\u001b[39m q3d\u001b[38;5;241m.\u001b[39mpost\u001b[38;5;241m.\u001b[39mavailable_report_quantities()\n\u001b[0;32m    234\u001b[0m \u001b[38;5;28mprint\u001b[39m(result)\n\u001b[0;32m    235\u001b[0m \u001b[38;5;66;03m#C(signal1_5,rectangle1)\u001b[39;00m\n",
      "File \u001b[1;32md:\\anaconda3\\envs\\qeda_env\\Lib\\site-packages\\ansys\\aedt\\core\\application\\analysis_3d.py:199\u001b[0m, in \u001b[0;36mFieldAnalysis3D.post\u001b[1;34m(self)\u001b[0m\n\u001b[0;32m    196\u001b[0m \u001b[38;5;28;01mif\u001b[39;00m \u001b[38;5;28mself\u001b[39m\u001b[38;5;241m.\u001b[39m_post \u001b[38;5;129;01mis\u001b[39;00m \u001b[38;5;28;01mNone\u001b[39;00m \u001b[38;5;129;01mand\u001b[39;00m \u001b[38;5;28mself\u001b[39m\u001b[38;5;241m.\u001b[39m_odesign:\n\u001b[0;32m    197\u001b[0m     \u001b[38;5;28;01mfrom\u001b[39;00m \u001b[38;5;21;01mansys\u001b[39;00m\u001b[38;5;21;01m.\u001b[39;00m\u001b[38;5;21;01maedt\u001b[39;00m\u001b[38;5;21;01m.\u001b[39;00m\u001b[38;5;21;01mcore\u001b[39;00m\u001b[38;5;21;01m.\u001b[39;00m\u001b[38;5;21;01mvisualization\u001b[39;00m\u001b[38;5;21;01m.\u001b[39;00m\u001b[38;5;21;01mpost\u001b[39;00m \u001b[38;5;28;01mimport\u001b[39;00m post_processor\n\u001b[1;32m--> 199\u001b[0m     \u001b[38;5;28mself\u001b[39m\u001b[38;5;241m.\u001b[39m_post \u001b[38;5;241m=\u001b[39m post_processor(\u001b[38;5;28mself\u001b[39m)\n\u001b[0;32m    200\u001b[0m \u001b[38;5;28;01mreturn\u001b[39;00m \u001b[38;5;28mself\u001b[39m\u001b[38;5;241m.\u001b[39m_post\n",
      "File \u001b[1;32md:\\anaconda3\\envs\\qeda_env\\Lib\\site-packages\\ansys\\aedt\\core\\visualization\\post\\__init__.py:63\u001b[0m, in \u001b[0;36mpost_processor\u001b[1;34m(app, project, design, version)\u001b[0m\n\u001b[0;32m     61\u001b[0m         \u001b[38;5;28;01mfrom\u001b[39;00m \u001b[38;5;21;01mansys\u001b[39;00m\u001b[38;5;21;01m.\u001b[39;00m\u001b[38;5;21;01maedt\u001b[39;00m\u001b[38;5;21;01m.\u001b[39;00m\u001b[38;5;21;01mcore\u001b[39;00m\u001b[38;5;21;01m.\u001b[39;00m\u001b[38;5;21;01mvisualization\u001b[39;00m\u001b[38;5;21;01m.\u001b[39;00m\u001b[38;5;21;01mpost\u001b[39;00m\u001b[38;5;21;01m.\u001b[39;00m\u001b[38;5;21;01mpost_common_3d\u001b[39;00m \u001b[38;5;28;01mimport\u001b[39;00m PostProcessor3D \u001b[38;5;28;01mas\u001b[39;00m PostProcessor\n\u001b[0;32m     62\u001b[0m \u001b[38;5;28;01mif\u001b[39;00m PostProcessor:\n\u001b[1;32m---> 63\u001b[0m     _post \u001b[38;5;241m=\u001b[39m PostProcessor(app)\n\u001b[0;32m     64\u001b[0m     app\u001b[38;5;241m.\u001b[39mlogger\u001b[38;5;241m.\u001b[39minfo_timer(\u001b[38;5;124m\"\u001b[39m\u001b[38;5;124mPost class has been initialized!\u001b[39m\u001b[38;5;124m\"\u001b[39m)\n\u001b[0;32m     65\u001b[0m     \u001b[38;5;28;01mreturn\u001b[39;00m _post\n",
      "File \u001b[1;32md:\\anaconda3\\envs\\qeda_env\\Lib\\site-packages\\ansys\\aedt\\core\\visualization\\post\\post_common_3d.py:90\u001b[0m, in \u001b[0;36mPostProcessor3D.__init__\u001b[1;34m(self, app)\u001b[0m\n\u001b[0;32m     88\u001b[0m \u001b[38;5;28mself\u001b[39m\u001b[38;5;241m.\u001b[39m_post_osolution \u001b[38;5;241m=\u001b[39m \u001b[38;5;28mself\u001b[39m\u001b[38;5;241m.\u001b[39m_app\u001b[38;5;241m.\u001b[39mosolution\n\u001b[0;32m     89\u001b[0m \u001b[38;5;28mself\u001b[39m\u001b[38;5;241m.\u001b[39mfield_plots \u001b[38;5;241m=\u001b[39m \u001b[38;5;28mself\u001b[39m\u001b[38;5;241m.\u001b[39m_get_fields_plot()\n\u001b[1;32m---> 90\u001b[0m PostProcessorCommon\u001b[38;5;241m.\u001b[39m\u001b[38;5;21m__init__\u001b[39m(\u001b[38;5;28mself\u001b[39m, app)\n\u001b[0;32m     91\u001b[0m \u001b[38;5;28mself\u001b[39m\u001b[38;5;241m.\u001b[39mfields_calculator \u001b[38;5;241m=\u001b[39m FieldsCalculator(app)\n\u001b[0;32m     92\u001b[0m app\u001b[38;5;241m.\u001b[39mlogger\u001b[38;5;241m.\u001b[39minfo_timer(\u001b[38;5;124m\"\u001b[39m\u001b[38;5;124mPostProcessor class has been initialized!\u001b[39m\u001b[38;5;124m\"\u001b[39m)\n",
      "File \u001b[1;32md:\\anaconda3\\envs\\qeda_env\\Lib\\site-packages\\ansys\\aedt\\core\\visualization\\post\\common.py:96\u001b[0m, in \u001b[0;36mPostProcessorCommon.__init__\u001b[1;34m(self, app)\u001b[0m\n\u001b[0;32m     94\u001b[0m \u001b[38;5;28;01mdef\u001b[39;00m \u001b[38;5;21m__init__\u001b[39m(\u001b[38;5;28mself\u001b[39m, app):\n\u001b[0;32m     95\u001b[0m     \u001b[38;5;28mself\u001b[39m\u001b[38;5;241m.\u001b[39m_app \u001b[38;5;241m=\u001b[39m app\n\u001b[1;32m---> 96\u001b[0m     \u001b[38;5;28mself\u001b[39m\u001b[38;5;241m.\u001b[39m_scratch \u001b[38;5;241m=\u001b[39m \u001b[38;5;28mself\u001b[39m\u001b[38;5;241m.\u001b[39m_app\u001b[38;5;241m.\u001b[39mworking_directory\n\u001b[0;32m     97\u001b[0m     \u001b[38;5;28mself\u001b[39m\u001b[38;5;241m.\u001b[39mplots \u001b[38;5;241m=\u001b[39m \u001b[38;5;28mself\u001b[39m\u001b[38;5;241m.\u001b[39m_get_plot_inputs()\n\u001b[0;32m     98\u001b[0m     \u001b[38;5;28mself\u001b[39m\u001b[38;5;241m.\u001b[39mreports_by_category \u001b[38;5;241m=\u001b[39m Reports(\u001b[38;5;28mself\u001b[39m, \u001b[38;5;28mself\u001b[39m\u001b[38;5;241m.\u001b[39m_app\u001b[38;5;241m.\u001b[39mdesign_type)\n",
      "File \u001b[1;32md:\\anaconda3\\envs\\qeda_env\\Lib\\site-packages\\ansys\\aedt\\core\\application\\design.py:1079\u001b[0m, in \u001b[0;36mDesign.working_directory\u001b[1;34m(self)\u001b[0m\n\u001b[0;32m   1068\u001b[0m \u001b[38;5;129m@property\u001b[39m\n\u001b[0;32m   1069\u001b[0m \u001b[38;5;28;01mdef\u001b[39;00m \u001b[38;5;21mworking_directory\u001b[39m(\u001b[38;5;28mself\u001b[39m) \u001b[38;5;241m-\u001b[39m\u001b[38;5;241m>\u001b[39m \u001b[38;5;28mstr\u001b[39m:\n\u001b[0;32m   1070\u001b[0m \u001b[38;5;250m    \u001b[39m\u001b[38;5;124;03m\"\"\"Path to the working directory.\u001b[39;00m\n\u001b[0;32m   1071\u001b[0m \n\u001b[0;32m   1072\u001b[0m \u001b[38;5;124;03m    Returns\u001b[39;00m\n\u001b[1;32m   (...)\u001b[0m\n\u001b[0;32m   1077\u001b[0m \n\u001b[0;32m   1078\u001b[0m \u001b[38;5;124;03m    \"\"\"\u001b[39;00m\n\u001b[1;32m-> 1079\u001b[0m     \u001b[38;5;28;01mif\u001b[39;00m \u001b[38;5;28mself\u001b[39m\u001b[38;5;241m.\u001b[39mdesign_name:\n\u001b[0;32m   1080\u001b[0m         name \u001b[38;5;241m=\u001b[39m \u001b[38;5;28mself\u001b[39m\u001b[38;5;241m.\u001b[39mdesign_name\u001b[38;5;241m.\u001b[39mreplace(\u001b[38;5;124m\"\u001b[39m\u001b[38;5;124m \u001b[39m\u001b[38;5;124m\"\u001b[39m, \u001b[38;5;124m\"\u001b[39m\u001b[38;5;124m_\u001b[39m\u001b[38;5;124m\"\u001b[39m)\n\u001b[0;32m   1081\u001b[0m     \u001b[38;5;28;01melse\u001b[39;00m:\n",
      "File \u001b[1;32md:\\anaconda3\\envs\\qeda_env\\Lib\\site-packages\\ansys\\aedt\\core\\application\\design.py:723\u001b[0m, in \u001b[0;36mDesign.design_name\u001b[1;34m(self)\u001b[0m\n\u001b[0;32m    721\u001b[0m     \u001b[38;5;28;01mreturn\u001b[39;00m \u001b[38;5;28;01mNone\u001b[39;00m\n\u001b[0;32m    722\u001b[0m \u001b[38;5;28mself\u001b[39m\u001b[38;5;241m.\u001b[39m_design_name \u001b[38;5;241m=\u001b[39m _retry_ntimes(\u001b[38;5;241m5\u001b[39m, \u001b[38;5;28mself\u001b[39m\u001b[38;5;241m.\u001b[39modesign\u001b[38;5;241m.\u001b[39mGetName)\n\u001b[1;32m--> 723\u001b[0m \u001b[38;5;28;01mif\u001b[39;00m \u001b[38;5;124m\"\u001b[39m\u001b[38;5;124m;\u001b[39m\u001b[38;5;124m\"\u001b[39m \u001b[38;5;129;01min\u001b[39;00m \u001b[38;5;28mself\u001b[39m\u001b[38;5;241m.\u001b[39m_design_name:\n\u001b[0;32m    724\u001b[0m     \u001b[38;5;28mself\u001b[39m\u001b[38;5;241m.\u001b[39m_design_name \u001b[38;5;241m=\u001b[39m \u001b[38;5;28mself\u001b[39m\u001b[38;5;241m.\u001b[39m_design_name\u001b[38;5;241m.\u001b[39msplit(\u001b[38;5;124m\"\u001b[39m\u001b[38;5;124m;\u001b[39m\u001b[38;5;124m\"\u001b[39m)[\u001b[38;5;241m1\u001b[39m]\n\u001b[0;32m    725\u001b[0m \u001b[38;5;28;01mreturn\u001b[39;00m \u001b[38;5;28mself\u001b[39m\u001b[38;5;241m.\u001b[39m_design_name\n",
      "\u001b[1;31mTypeError\u001b[0m: argument of type 'NoneType' is not iterable"
     ]
    }
   ],
   "source": [
    "import sys\n",
    "sys.path.append('..')\n",
    "\n",
    "from renderer.q3d.capative import capacitance\n",
    "import os\n",
    "gds_name = 'QRT.gds'\n",
    "\n",
    "base_dir = os.getcwd()  # 当前工作目录\n",
    "gds_path = os.path.join(base_dir, gds_name)\n",
    "\n",
    "ei = capacitance(project = 'project' , version = '2024.1')\n",
    "\n",
    "ei.run_q3d_extraction_from_gds(gds_name)"
   ]
  }
 ],
 "metadata": {
  "kernelspec": {
   "display_name": "qeda_env",
   "language": "python",
   "name": "python3"
  },
  "language_info": {
   "codemirror_mode": {
    "name": "ipython",
    "version": 3
   },
   "file_extension": ".py",
   "mimetype": "text/x-python",
   "name": "python",
   "nbconvert_exporter": "python",
   "pygments_lexer": "ipython3",
   "version": "3.11.5"
  }
 },
 "nbformat": 4,
 "nbformat_minor": 5
}
